<mujoco model="ur5e">
  <compiler angle="radian" meshdir="assets_clone" texturedir="assets_clone" autolimits="true"/>

  <option integrator="implicitfast"/>

  <default>
    <default class="ur5e">
      <material specular="0.5" shininess="0.25"/>
      <joint axis="0 1 0" range="-6.28319 6.28319" armature="0.1"/>
      <general gaintype="fixed" biastype="affine" ctrlrange="-6.2831 6.2831" gainprm="2000" biasprm="0 -2000 -300"
        forcerange="-150 150"/>
      <default class="size3">
        <default class="size3_limited">
          <joint range="-3.1415 3.1415"/>
          <general ctrlrange="-3.1415 3.1415"/>
        </default>
      </default>
      <default class="size1">
        <general gainprm="500" biasprm="0 -500 -100" forcerange="-28 28"/>
      </default>
      <default class="visual">
        <geom type="mesh" contype="0" conaffinity="0" group="2"/>
      </default>
      <default class="collision">
        <geom type="capsule" group="3"/>
        <default class="eef_collision">
          <geom type="cylinder"/>
        </default>
      </default>
      <site size="0.001" rgba="0.5 0.5 0.5 0.3" group="4"/>
    </default>

    <default class="allegro_right">
      <joint axis="0 1 0" damping=".1"/>
      <position kp="5"/>
      <geom density="800"/>
      <default class="allegro_visual">
        <geom type="mesh" contype="0" conaffinity="0" group="2" material="black"/>
        <default class="palm_visual">
          <geom mesh="base_link"/>
        </default>
        <default class="base_visual">
          <geom mesh="link_0.0"/>
        </default>
        <default class="proximal_visual">
          <geom mesh="link_1.0"/>
        </default>
        <default class="medial_visual">
          <geom mesh="link_2.0"/>
        </default>
        <default class="distal_visual">
          <geom mesh="link_3.0"/>
        </default>
        <default class="fingertip_visual">
          <geom pos="0 0 0.0267" material="allegro_white" mesh="link_3.0_tip"/>
        </default>
        <default class="thumbtip_visual">
          <geom pos="0 0 0.0423" material="allegro_white" mesh="link_15.0_tip"/>
        </default>
      </default>

      <default class="allegro_collision">
        <geom group="3" type="box" mass="0" 
        friction="1.5 0.5 0.1" 
        condim="6" 
        solref="0.01 1.0" 
        solimp="0.9 0.95 0.001"/>
        <default class="palm_collision">
          <geom size="0.0204 0.0565 0.0475" pos="-0.0093 0 -0.0475"/>
        </default>
        <default class="base_collision">
          <geom size="0.0098 0.01375 0.0082" pos="0 0 0.0082"/>
          <default class="thumb_base_collision">
            <geom size="0.0179 0.017 0.02275" pos="-0.0179 0.009 0.0145"/>
          </default>
        </default>
        <default class="proximal_collision">
          <geom size="0.0098 0.01375 0.027" pos="0 0 0.027"/>
          <default class="thumb_proximal_collision">
            <geom size="0.0098 0.01375 0.00885" pos="0 0 0.00885"/>
          </default>
        </default>
        <default class="medial_collision">
          <geom size="0.0098 0.01375 0.0192" pos="0 0 0.0192"/>
          <default class="thumb_medial_collision">
            <geom size="0.0098 0.01375 0.0257" pos="0 0 0.0257"/>
          </default>
        </default>
        <default class="distal_collision">
          <geom size="0.0098 0.01375 0.008" pos="0 0 0.008"/>
          <default class="thumb_distal_collision">
            <geom size="0.0098 0.01375 0.0157" pos="0 0 0.0157"/>
          </default>
        </default>
        <default class="fingertip_collision">
        <!--손가락 마찰력 friction-->
          <geom type="capsule" size="0.012 0.01" pos="0 0 0.019" friction="1.5 0.5 0.1"/>
          <default class="thumbtip_collision">
            <geom type="capsule" size="0.012 0.008" pos="0 0 0.035" friction="1.5 0.5 0.1"/>
          </default>
        </default>
      </default>

      <default class="base">
        <joint axis="0 0 1" range="-0.47 0.47"/>
        <position ctrlrange="-0.47 0.47"/>
      </default>
      <default class="proximal">
        <joint range="-0.196 1.61"/>
        <position ctrlrange="-0.196 1.61"/>
      </default>
      <default class="medial">
        <joint range="-0.174 1.709"/>
        <position ctrlrange="-0.174 1.709"/>
      </default>
      <default class="distal">
        <joint range="-0.227 1.618"/>
        <position ctrlrange="-0.227 1.618"/>
      </default>
      <default class="thumb_base">
        <joint axis="-1 0 0" range="0.263 1.396"/>
        <position ctrlrange="0.263 1.396"/>
      </default>
      <default class="thumb_proximal">
        <joint axis="0 0 1" range="-0.105 1.163"/>
        <position ctrlrange="-0.105 1.163"/>
      </default>
      <default class="thumb_medial">
        <joint range="-0.189 1.644"/>
        <position ctrlrange="-0.189 1.644"/>
      </default>
      <default class="thumb_distal">
        <joint range="-0.162 1.719"/>
        <position ctrlrange="-0.162 1.719"/>
      </default>
    </default>
  </default>

  <asset>
    <texture type="2d" name="apple_tex" file="apple/texture_map.png"/>
        
    <material name="apple_mat" texture="apple_tex" specular="0.2" shininess="0.2"/>
        
    <mesh name="apple_mesh" file="apple/textured.obj" scale="1 1 1"/>
  </asset>

  <asset>
    <material class="ur5e" name="black" rgba="0.033 0.033 0.033 1"/>
    <material class="ur5e" name="jointgray" rgba="0.278 0.278 0.278 1"/>
    <material class="ur5e" name="linkgray" rgba="0.82 0.82 0.82 1"/>
    <material class="ur5e" name="urblue" rgba="0.49 0.678 0.8 1"/>

    <mesh file="base_0.obj"/>
    <mesh file="base_1.obj"/>
    <mesh file="shoulder_0.obj"/>
    <mesh file="shoulder_1.obj"/>
    <mesh file="shoulder_2.obj"/>
    <mesh file="upperarm_0.obj"/>
    <mesh file="upperarm_1.obj"/>
    <mesh file="upperarm_2.obj"/>
    <mesh file="upperarm_3.obj"/>
    <mesh file="forearm_0.obj"/>
    <mesh file="forearm_1.obj"/>
    <mesh file="forearm_2.obj"/>
    <mesh file="forearm_3.obj"/>
    <mesh file="wrist1_0.obj"/>
    <mesh file="wrist1_1.obj"/>
    <mesh file="wrist1_2.obj"/>
    <mesh file="wrist2_0.obj"/>
    <mesh file="wrist2_1.obj"/>
    <mesh file="wrist2_2.obj"/>
    <mesh file="wrist3.obj"/>
  </asset>

  <asset>
    <material name="allegro_black" rgba="0.2 0.2 0.2 1"/>
    <material name="allegro_white" rgba="0.9 0.9 0.9 1"/>

    <mesh file="base_link.stl"/>
    <mesh file="link_0.0.stl"/>
    <mesh file="link_1.0.stl"/>
    <mesh file="link_2.0.stl"/>
    <mesh file="link_3.0.stl"/>
    <mesh file="link_3.0_tip.stl"/>
    <mesh file="link_12.0_right.stl"/>
    <mesh file="link_13.0.stl"/>
    <mesh file="link_14.0.stl"/>
    <mesh file="link_15.0.stl"/>
    <mesh file="link_15.0_tip.stl"/>
  </asset>

  <asset>
    <material name="trunk_mat" rgba="0.4 0.2 0.1 1" specular="0.1" shininess="0.1"/>
    <material name="leaf_mat" rgba="0.1 0.5 0.1 0.8" specular="0.1" shininess="0.1"/>
  </asset>

  <equality>
      <weld name="apple_1_weld" body1="apple_1" body2="tree_branch_1" 
            solref="0.02 1" solimp="0.9 0.95 0.001"/>
  </equality>

  <equality>
      <weld name="apple_2_weld" body1="apple_2" body2="tree_branch_1" 
            solref="0.02 1" solimp="0.9 0.95 0.001"/>
  </equality>

  <equality>
      <weld name="apple_3_weld" body1="apple_3" body2="tree_branch_1" 
            solref="0.02 1" solimp="0.9 0.95 0.001"/>
  </equality>

  <sensor>
      <force name="apple_force_sensor_1" site="apple_force_site_1"/>
  </sensor>

  <sensor>
      <force name="apple_force_sensor_2" site="apple_force_site_2"/>
  </sensor>

  <sensor>
      <force name="apple_force_sensor_3" site="apple_force_site_3"/>
  </sensor>

  <worldbody>
    <!-- Custom_S -->
    <geom name="floor" type="plane" pos="0 0 0" size="5 5 0.1" rgba="0.34 0.49 0.27 1" friction="1 0.005 0.0001"/>

    <body name="harvest_basket" pos="0.0 0.5 0.02">
      <geom name="basket_bottom" type="box" size="0.2 0.15 0.01" rgba="0.82 0.62 0.44 1" friction="1 0.05 0.01"/>
      
      <geom name="wall_front" type="box" size="0.2 0.01 0.1" pos="0 0.14 0.1" rgba="0.82 0.62 0.44 1"/>
      <geom name="wall_back" type="box" size="0.2 0.01 0.1" pos="0 -0.14 0.1" rgba="0.82 0.62 0.44 1"/>
      <geom name="wall_left" type="box" size="0.01 0.13 0.1" pos="-0.19 0 0.1" rgba="0.82 0.62 0.44 1"/>
      <geom name="wall_right" type="box" size="0.01 0.13 0.1" pos="0.19 0 0.1" rgba="0.82 0.62 0.44 1"/>
      
      <site name="basket_center" pos="0 0 0.05" size="0.01" rgba="1 0 0 0"/>
    </body>

    <body name="apple_tree_1" pos="-0.6 -0.6 0"> 
      <geom name="tree_trunk" type="cylinder" size="0.04 0.4" pos="0 0 0.4" material="trunk_mat"/>
      <geom name="tree_leaves" type="sphere" size="0.3" pos="0 0 1.0" material="leaf_mat" contype="0" conaffinity="0"/>

      <body name="tree_branch_1" pos="0 0 0.6" axisangle="0 1 1 1.92">
        <geom name="branch_1_geom" type="capsule" size="0.015 0.18" pos="0 0 0.18" material="trunk_mat" contype="0" conaffinity="0"/>
        <site name="hook_apple_3" pos="0 0 0.36" size="0.01" rgba="1 0 0 1"/> 
      </body>

      <body name="tree_branch_2" pos="0 0 0.6" axisangle="1 0 0 -1.92">
        <geom name="branch_2_geom" type="capsule" size="0.015 0.12" pos="0 0 0.12" material="trunk_mat" contype="0" conaffinity="0"/>
        <site name="hook_apple_4" pos="0 0 0.24" size="0.01" rgba="1 0 0 1"/>
      </body>
    </body>

    <body name="apple_1" pos="-0.49 -0.52 0.77">
        <freejoint name="joint_apple_1"/>
        <geom name="apple_1_geom" type="mesh" mesh="apple_mesh" material="apple_mat" mass="0.1" friction="2.0 0.5 0.01"/>
        <site name="apple_force_site_1" pos="0 0 0"/>
    </body>

    <body name="apple_2" pos="-0.41 -0.61 0.61">
        <freejoint name="joint_apple_2"/>
        <geom name="apple_2_geom" type="mesh" mesh="apple_mesh" material="apple_mat" mass="0.1" friction="2.0 0.5 0.01"/>
        <site name="apple_force_site_2" pos="0 0 0"/>
    </body>

    <body name="apple_3" pos="-0.38 -0.48 0.40">
        <freejoint name="joint_apple_3"/>
        <geom name="apple_3_geom" type="mesh" mesh="apple_mesh" material="apple_mat" mass="0.1" friction="2.0 0.5 0.01"/>
        <site name="apple_force_site_3" pos="0 0 0"/>
    </body>

    <body name="head_camera" pos="0.0 -0.3 1.0">
      <joint name="head_x_joint" type="hinge" axis="1 0 0" range="-3.14 3.14" limited="true" damping="0.5"/>
      <joint name="head_y_joint" type="hinge" axis="0 1 0" range="-3.14 3.14" limited="true" damping="0.5"/>
      <joint name="head_z_joint" type="hinge" axis="0 0 1" range="-3.14 3.14" limited="true" damping="0.5"/>

      <camera name="head_cam"
          pos="0 0 0"
          quat="0.7071 0 0 0.7071"
          fovy="60"/>
            
      <geom name="head_cam_marker"
          type="sphere"
          size="0.03"
          pos="0 0 0"
          quat="0.7071 0 0 0.7071"
          rgba="0.49 0.67 0.8 1.0"
          contype="0" conaffinity="0"/>
                          
      <geom name="head_black_dot"
          type="sphere"
          size="0.02 0.02 0.02"
          pos="0 0 -0.02"
          quat="0.7071 0 0 0.7071"
          rgba="0 0 0 1"
          contype="0" conaffinity="0"/>
    </body>
    <!-- E_Custom -->
    <light name="spotlight" mode="targetbodycom" target="wrist_2_link" pos="0 -1 2"/>
    <body name="base" quat="0 0 0 -1" childclass="ur5e">
      <inertial mass="4.0" pos="0 0 0" diaginertia="0.00443333156 0.00443333156 0.0072"/>
      <geom mesh="base_0" material="black" class="visual"/>
      <geom mesh="base_1" material="jointgray" class="visual"/>
      <body name="shoulder_link" pos="0 0 0.163">
        <inertial mass="3.7" pos="0 0 0" diaginertia="0.0102675 0.0102675 0.00666"/>
        <joint name="shoulder_pan_joint" class="size3" axis="0 0 1"/>
        <geom mesh="shoulder_0" material="urblue" class="visual"/>
        <geom mesh="shoulder_1" material="black" class="visual"/>
        <geom mesh="shoulder_2" material="jointgray" class="visual"/>
        <geom class="collision" size="0.06 0.06" pos="0 0 -0.04"/>
        <body name="upper_arm_link" pos="0 0.138 0" quat="1 0 1 0">
          <inertial mass="8.393" pos="0 0 0.2125" diaginertia="0.133886 0.133886 0.0151074"/>
          <joint name="shoulder_lift_joint" class="size3"/>
          <geom mesh="upperarm_0" material="linkgray" class="visual"/>
          <geom mesh="upperarm_1" material="black" class="visual"/>
          <geom mesh="upperarm_2" material="jointgray" class="visual"/>
          <geom mesh="upperarm_3" material="urblue" class="visual"/>
          <geom class="collision" pos="0 -0.04 0" quat="1 1 0 0" size="0.06 0.06"/>
          <geom class="collision" size="0.05 0.2" pos="0 0 0.2"/>
          <body name="forearm_link" pos="0 -0.131 0.425">
            <inertial mass="2.275" pos="0 0 0.196" diaginertia="0.0311796 0.0311796 0.004095"/>
            <joint name="elbow_joint" class="size3_limited"/>
            <geom mesh="forearm_0" material="urblue" class="visual"/>
            <geom mesh="forearm_1" material="linkgray" class="visual"/>
            <geom mesh="forearm_2" material="black" class="visual"/>
            <geom mesh="forearm_3" material="jointgray" class="visual"/>
            <geom class="collision" pos="0 0.08 0" quat="1 1 0 0" size="0.055 0.06"/>
            <geom class="collision" size="0.038 0.19" pos="0 0 0.2"/>
            <body name="wrist_1_link" pos="0 0 0.392" quat="1 0 1 0">
              <inertial mass="1.219" pos="0 0.127 0" diaginertia="0.0025599 0.0025599 0.0021942"/>
              <joint name="wrist_1_joint" class="size1"/>
              <geom mesh="wrist1_0" material="black" class="visual"/>
              <geom mesh="wrist1_1" material="urblue" class="visual"/>
              <geom mesh="wrist1_2" material="jointgray" class="visual"/>
              <geom class="collision" pos="0 0.05 0" quat="1 1 0 0" size="0.04 0.07"/>
              <body name="wrist_2_link" pos="0 0.127 0">
                <inertial mass="1.219" pos="0 0 0.1" diaginertia="0.0025599 0.0025599 0.0021942"/>
                <joint name="wrist_2_joint" axis="0 0 1" class="size1"/>
                <geom mesh="wrist2_0" material="black" class="visual"/>
                <geom mesh="wrist2_1" material="urblue" class="visual"/>
                <geom mesh="wrist2_2" material="jointgray" class="visual"/>
                <geom class="collision" size="0.04 0.06" pos="0 0 0.04"/>
                <geom class="collision" pos="0 0.02 0.1" quat="1 1 0 0" size="0.04 0.04"/>
                <body name="wrist_3_link" pos="0 0 0.1">
                  <body name="allegro_right_palm" pos=" 0 0.1 0.05" quat="0.7071068 0 0 0.7071068" childclass="allegro_right">
                    <site name="palm_center" type="box" pos="0 0 -0.035" size="0.01" rgba="1 1 1 1" group="1"/>
                    <!-- <inertial mass="0.4154" pos="0 0 0.0475" diaginertia="1e-4 1e-4 1e-4"/> -->
                    <geom class="palm_visual" mesh="base_link"/>
                    <geom class="palm_collision"/>
                    <!-- First finger -->
                    <body name="ff_base" pos="0 0.0435 -0.001542" quat="0.999048 -0.0436194 0 0">
                      <joint name="ffj0" class="base"/>
                      <geom class="base_visual"/>
                      <geom class="base_collision"/>
                      <body name="ff_proximal" pos="0 0 0.0164">
                        <joint name="ffj1" class="proximal"/>
                        <geom class="proximal_visual"/>
                        <geom class="proximal_collision"/>
                        <body name="ff_medial" pos="0 0 0.054">
                          <joint name="ffj2" class="medial"/>
                          <geom class="medial_visual"/>
                          <geom class="medial_collision"/>
                          <body name="ff_distal" pos="0 0 0.0384">
                            <joint name="ffj3" class="distal"/>
                            <geom class="distal_visual"/>
                            <geom class="distal_collision"/>
                            <body name="ff_tip">
                              <geom class="fingertip_visual"/>
                              <geom class="fingertip_collision"/>
                            </body>
                          </body>
                        </body>
                      </body>
                    </body>
                    <!-- Middle finger -->
                    <body name="mf_base" pos="0 0 0.0007">
                      <joint name="mfj0" class="base"/>
                      <geom class="base_visual"/>
                      <geom class="base_collision"/>
                      <body name="mf_proximal" pos="0 0 0.0164">
                        <joint name="mfj1" class="proximal"/>
                        <geom class="proximal_visual"/>
                        <geom class="proximal_collision"/>
                        <body name="mf_medial" pos="0 0 0.054">
                          <joint name="mfj2" class="medial"/>
                          <geom class="medial_visual"/>
                          <geom class="medial_collision"/>
                          <body name="mf_distal" pos="0 0 0.0384">
                            <joint name="mfj3" class="distal"/>
                            <geom class="distal_visual"/>
                            <geom class="distal_collision"/>
                            <body name="mf_tip">
                              <geom class="fingertip_visual"/>
                              <geom class="fingertip_collision"/>
                            </body>
                          </body>
                        </body>
                      </body>
                    </body>
                    <!-- Ring finger -->
                    <body name="rf_base" pos="0 -0.0435 -0.001542" quat="0.999048 0.0436194 0 0">
                      <joint name="rfj0" class="base"/>
                      <geom class="base_visual"/>
                      <geom class="base_collision"/>
                      <body name="rf_proximal" pos="0 0 0.0164">
                        <joint name="rfj1" class="proximal"/>
                        <geom class="proximal_visual"/>
                        <geom class="proximal_collision"/>
                        <body name="rf_medial" pos="0 0 0.054">
                          <joint name="rfj2" class="medial"/>
                          <geom class="medial_visual"/>
                          <geom class="medial_collision"/>
                          <body name="rf_distal" pos="0 0 0.0384">
                            <joint name="rfj3" class="distal"/>
                            <geom class="distal_visual"/>
                            <geom class="distal_collision"/>
                            <body name="rf_tip">
                              <geom class="fingertip_visual"/>
                              <geom class="fingertip_collision"/>
                            </body>
                          </body>
                        </body>
                      </body>
                    </body>
                    <!-- Thumb -->
                    <body name="th_base" pos="-0.0182 0.019333 -0.045987" quat="0.477714 -0.521334 -0.521334 -0.477714">
                      <joint name="thj0" class="thumb_base"/>
                      <geom class="visual" mesh="link_12.0_right"/>
                      <geom class="thumb_base_collision"/>
                      <body name="th_proximal" pos="-0.027 0.005 0.0399">
                        <joint name="thj1" class="thumb_proximal"/>
                        <geom class="visual" mesh="link_13.0"/>
                        <geom class="thumb_proximal_collision"/>
                        <body name="th_medial" pos="0 0 0.0177">
                          <joint name="thj2" class="thumb_medial"/>
                          <geom class="visual" mesh="link_14.0"/>
                          <geom class="thumb_medial_collision"/>
                          <body name="th_distal" pos="0 0 0.0514">
                            <joint name="thj3" class="thumb_distal"/>
                            <geom class="visual" mesh="link_15.0"/>
                            <geom class="thumb_distal_collision"/>
                            <body name="th_tip">
                              <geom class="thumbtip_visual"/>
                              <geom class="thumbtip_collision"/>
                            </body>
                          </body>
                        </body>
                      </body>
                    </body>
                  </body>
		    
                  <inertial mass="0.1889" pos="0 0.0771683 0" quat="1 0 0 1"
                    diaginertia="0.000132134 9.90863e-05 9.90863e-05"/>
                  <joint name="wrist_3_joint" class="size1"/>
                  <geom material="linkgray" mesh="wrist3" class="visual"/>
                  <geom class="eef_collision" pos="0 0.08 0" quat="1 1 0 0" size="0.04 0.02"/>
                  <site name="attachment_site" pos="0 0.1 0" quat="-1 1 0 0"/>
                </body>
              </body>
            </body>
          </body>
        </body>
      </body>
    </body>
  </worldbody>

  <actuator>
    <general class="size3" name="shoulder_pan" joint="shoulder_pan_joint"/>
    <general class="size3" name="shoulder_lift" joint="shoulder_lift_joint"/>
    <general class="size3_limited" name="elbow" joint="elbow_joint"/>
    <general class="size1" name="wrist_1" joint="wrist_1_joint"/>
    <general class="size1" name="wrist_2" joint="wrist_2_joint"/>
    <general class="size1" name="wrist_3" joint="wrist_3_joint"/>
  </actuator>

  <actuator>
    <position name="ffa0" joint="ffj0" class="base"/>
    <position name="ffa1" joint="ffj1" class="proximal"/>
    <position name="ffa2" joint="ffj2" class="medial"/>
    <position name="ffa3" joint="ffj3" class="distal"/>
    <position name="mfa0" joint="mfj0" class="base"/>
    <position name="mfa1" joint="mfj1" class="proximal"/>
    <position name="mfa2" joint="mfj2" class="medial"/>
    <position name="mfa3" joint="mfj3" class="distal"/>
    <position name="rfa0" joint="rfj0" class="base"/>
    <position name="rfa1" joint="rfj1" class="proximal"/>
    <position name="rfa2" joint="rfj2" class="medial"/>
    <position name="rfa3" joint="rfj3" class="distal"/>
    <position name="tha0" joint="thj0" class="thumb_base"/>
    <position name="tha1" joint="thj1" class="thumb_proximal"/>
    <position name="tha2" joint="thj2" class="thumb_medial"/>
    <position name="tha3" joint="thj3" class="thumb_distal"/>
  </actuator>

  <actuator>
    <position name="head_x_servo" joint="head_x_joint" kp="20" ctrlrange="-3.14 3.14" forcelimited="true" forcerange="-10 10"/>
    <position name="head_y_servo" joint="head_y_joint" kp="20" ctrlrange="-3.14 3.14" forcelimited="true" forcerange="-10 10"/>
    <position name="head_z_servo" joint="head_z_joint" kp="20" ctrlrange="-3.14 3.14" forcelimited="true" forcerange="-10 10"/>
  </actuator>

  <contact>
    <exclude body1="allegro_right_palm" body2="ff_base"/>
    <exclude body1="allegro_right_palm" body2="mf_base"/>
    <exclude body1="allegro_right_palm" body2="rf_base"/>
    <exclude body1="allegro_right_palm" body2="th_base"/>
    <exclude body1="allegro_right_palm" body2="th_proximal"/>
  </contact>

  <keyframe>
    <key name="home" qpos="-1.5708 -1.5708 1.5708 -1.5708 -1.5708 0" ctrl="-1.5708 -1.5708 1.5708 -1.5708 -1.5708 0"/>
  </keyframe>
</mujoco>